[2018-09-21 20:11:43 +0000] [21] [INFO] Starting gunicorn 19.5.0
[2018-09-21 20:11:43 +0000] [21] [INFO] Listening at: http://0.0.0.0:9000 (21)
[2018-09-21 20:11:43 +0000] [21] [INFO] Using worker: sync
[2018-09-21 20:11:43 +0000] [24] [INFO] Booting worker with pid: 24
[2018-09-21 20:11:43 +0000] [26] [INFO] Booting worker with pid: 26
[2018-09-21 15:21:01 -0500] [26] [INFO] Worker reloading: /home/django_app/c_olimpo/admin.py modified
[2018-09-21 15:21:01 -0500] [24] [INFO] Worker reloading: /home/django_app/c_olimpo/admin.py modified
[2018-09-21 15:21:01 -0500] [26] [INFO] Worker exiting (pid: 26)
[2018-09-21 15:21:01 -0500] [24] [INFO] Worker exiting (pid: 24)
[2018-09-21 20:21:01 +0000] [30] [INFO] Booting worker with pid: 30
[2018-09-21 20:21:01 +0000] [32] [INFO] Booting worker with pid: 32
[2018-09-21 20:22:53 +0000] [21] [CRITICAL] WORKER TIMEOUT (pid:32)
[2018-09-21 20:22:53 +0000] [21] [CRITICAL] WORKER TIMEOUT (pid:30)
[2018-09-21 15:22:53 -0500] [32] [INFO] Worker exiting (pid: 32)
[2018-09-21 20:22:53 +0000] [81] [INFO] Booting worker with pid: 81
[2018-09-21 20:22:53 +0000] [83] [INFO] Booting worker with pid: 83
[2018-09-21 20:23:30 +0000] [21] [CRITICAL] WORKER TIMEOUT (pid:81)
[2018-09-21 20:23:30 +0000] [21] [CRITICAL] WORKER TIMEOUT (pid:83)
[2018-09-21 15:23:30 -0500] [81] [INFO] Worker exiting (pid: 81)
[2018-09-21 15:23:30 -0500] [83] [INFO] Worker exiting (pid: 83)
[2018-09-21 20:23:30 +0000] [106] [INFO] Booting worker with pid: 106
[2018-09-21 20:23:30 +0000] [108] [INFO] Booting worker with pid: 108
[2018-09-21 20:24:01 +0000] [21] [CRITICAL] WORKER TIMEOUT (pid:106)
[2018-09-21 20:24:01 +0000] [21] [CRITICAL] WORKER TIMEOUT (pid:108)
[2018-09-21 15:24:01 -0500] [106] [INFO] Worker exiting (pid: 106)
[2018-09-21 15:24:01 -0500] [108] [INFO] Worker exiting (pid: 108)
[2018-09-21 20:24:01 +0000] [120] [INFO] Booting worker with pid: 120
[2018-09-21 20:24:02 +0000] [123] [INFO] Booting worker with pid: 123
Not Found: /favicon.ico
[2018-09-21 15:33:09 -0500] [120] [INFO] Worker reloading: /home/django_app/c_olimpo/admin.py modified
[2018-09-21 15:33:09 -0500] [123] [INFO] Worker reloading: /home/django_app/c_olimpo/admin.py modified
[2018-09-21 15:33:09 -0500] [120] [INFO] Worker exiting (pid: 120)
[2018-09-21 15:33:09 -0500] [123] [INFO] Worker exiting (pid: 123)
[2018-09-21 20:33:09 +0000] [154] [INFO] Booting worker with pid: 154
[2018-09-21 20:33:09 +0000] [156] [INFO] Booting worker with pid: 156
[2018-09-21 20:35:49 +0000] [21] [CRITICAL] WORKER TIMEOUT (pid:154)
[2018-09-21 20:35:49 +0000] [21] [CRITICAL] WORKER TIMEOUT (pid:156)
[2018-09-21 15:35:49 -0500] [156] [INFO] Worker exiting (pid: 156)
[2018-09-21 20:35:49 +0000] [179] [INFO] Booting worker with pid: 179
[2018-09-21 20:35:49 +0000] [181] [INFO] Booting worker with pid: 181
[2018-09-21 20:36:20 +0000] [21] [CRITICAL] WORKER TIMEOUT (pid:179)
[2018-09-21 20:36:20 +0000] [21] [CRITICAL] WORKER TIMEOUT (pid:181)
[2018-09-21 15:36:20 -0500] [179] [INFO] Worker exiting (pid: 179)
[2018-09-21 15:36:20 -0500] [181] [INFO] Worker exiting (pid: 181)
[2018-09-21 20:36:20 +0000] [189] [INFO] Booting worker with pid: 189
[2018-09-21 20:36:20 +0000] [191] [INFO] Booting worker with pid: 191
[2018-09-21 20:36:51 +0000] [21] [CRITICAL] WORKER TIMEOUT (pid:189)
[2018-09-21 20:36:51 +0000] [21] [CRITICAL] WORKER TIMEOUT (pid:191)
[2018-09-21 15:36:51 -0500] [189] [INFO] Worker exiting (pid: 189)
[2018-09-21 15:36:51 -0500] [191] [INFO] Worker exiting (pid: 191)
[2018-09-21 20:36:52 +0000] [195] [INFO] Booting worker with pid: 195
[2018-09-21 20:36:52 +0000] [198] [INFO] Booting worker with pid: 198
[2018-09-21 20:38:32 +0000] [21] [CRITICAL] WORKER TIMEOUT (pid:195)
[2018-09-21 20:38:32 +0000] [21] [CRITICAL] WORKER TIMEOUT (pid:198)
[2018-09-21 15:38:32 -0500] [198] [INFO] Worker exiting (pid: 198)
[2018-09-21 20:38:32 +0000] [217] [INFO] Booting worker with pid: 217
[2018-09-21 20:38:32 +0000] [219] [INFO] Booting worker with pid: 219
[2018-09-21 20:40:41 +0000] [21] [CRITICAL] WORKER TIMEOUT (pid:217)
[2018-09-21 20:40:41 +0000] [21] [CRITICAL] WORKER TIMEOUT (pid:219)
[2018-09-21 15:40:41 -0500] [217] [INFO] Worker exiting (pid: 217)
[2018-09-21 20:40:41 +0000] [284] [INFO] Booting worker with pid: 284
[2018-09-21 20:40:41 +0000] [287] [INFO] Booting worker with pid: 287
[2018-09-21 20:42:05 +0000] [15] [INFO] Starting gunicorn 19.5.0
[2018-09-21 20:42:05 +0000] [15] [INFO] Listening at: http://0.0.0.0:9000 (15)
[2018-09-21 20:42:05 +0000] [15] [INFO] Using worker: sync
[2018-09-21 20:42:05 +0000] [18] [INFO] Booting worker with pid: 18
[2018-09-21 20:42:05 +0000] [21] [INFO] Booting worker with pid: 21
[2018-09-21 20:44:03 +0000] [15] [CRITICAL] WORKER TIMEOUT (pid:18)
[2018-09-21 20:44:03 +0000] [15] [CRITICAL] WORKER TIMEOUT (pid:21)
[2018-09-21 15:44:03 -0500] [18] [INFO] Worker exiting (pid: 18)
[2018-09-21 20:44:03 +0000] [38] [INFO] Booting worker with pid: 38
[2018-09-21 20:44:03 +0000] [40] [INFO] Booting worker with pid: 40
[2018-09-21 20:44:37 +0000] [15] [CRITICAL] WORKER TIMEOUT (pid:40)
[2018-09-21 20:44:37 +0000] [15] [CRITICAL] WORKER TIMEOUT (pid:38)
[2018-09-21 15:44:37 -0500] [40] [INFO] Worker exiting (pid: 40)
[2018-09-21 15:44:37 -0500] [38] [INFO] Worker exiting (pid: 38)
[2018-09-21 20:44:38 +0000] [44] [INFO] Booting worker with pid: 44
[2018-09-21 20:44:38 +0000] [46] [INFO] Booting worker with pid: 46
[2018-09-21 20:45:09 +0000] [15] [CRITICAL] WORKER TIMEOUT (pid:44)
[2018-09-21 20:45:09 +0000] [15] [CRITICAL] WORKER TIMEOUT (pid:46)
[2018-09-21 15:45:09 -0500] [44] [INFO] Worker exiting (pid: 44)
[2018-09-21 15:45:09 -0500] [46] [INFO] Worker exiting (pid: 46)
[2018-09-21 20:45:09 +0000] [50] [INFO] Booting worker with pid: 50
[2018-09-21 20:45:09 +0000] [52] [INFO] Booting worker with pid: 52
[2018-09-21 21:22:49 +0000] [15] [INFO] Starting gunicorn 19.5.0
[2018-09-21 21:22:49 +0000] [15] [INFO] Listening at: http://0.0.0.0:9000 (15)
[2018-09-21 21:22:49 +0000] [15] [INFO] Using worker: sync
[2018-09-21 21:22:49 +0000] [18] [INFO] Booting worker with pid: 18
[2018-09-21 21:22:49 +0000] [21] [INFO] Booting worker with pid: 21
[2018-09-21 16:43:33 -0500] [18] [INFO] Worker reloading: /home/django_app/project/settings.py modified
[2018-09-21 16:43:33 -0500] [21] [INFO] Worker reloading: /home/django_app/project/settings.py modified
[2018-09-21 16:43:33 -0500] [18] [INFO] Worker exiting (pid: 18)
[2018-09-21 16:43:33 -0500] [21] [INFO] Worker exiting (pid: 21)
[2018-09-21 21:43:33 +0000] [35] [INFO] Booting worker with pid: 35
[2018-09-21 21:43:33 +0000] [37] [INFO] Booting worker with pid: 37
Internal Server Error: /media/A201.pdf
Traceback (most recent call last):
  File "/usr/local/lib/python3.5/site-packages/django/core/handlers/exception.py", line 35, in inner
    response = get_response(request)
  File "/usr/local/lib/python3.5/site-packages/django/utils/deprecation.py", line 93, in __call__
    response = self.process_request(request)
  File "/usr/local/lib/python3.5/site-packages/django/middleware/common.py", line 60, in process_request
    if self.should_redirect_with_slash(request):
  File "/usr/local/lib/python3.5/site-packages/django/middleware/common.py", line 78, in should_redirect_with_slash
    not is_valid_path(request.path_info, urlconf) and
  File "/usr/local/lib/python3.5/site-packages/django/urls/base.py", line 155, in is_valid_path
    resolve(path, urlconf)
  File "/usr/local/lib/python3.5/site-packages/django/urls/base.py", line 24, in resolve
    return get_resolver(urlconf).resolve(path)
  File "/usr/local/lib/python3.5/site-packages/django/urls/resolvers.py", line 494, in resolve
    for pattern in self.url_patterns:
  File "/usr/local/lib/python3.5/site-packages/django/utils/functional.py", line 36, in __get__
    res = instance.__dict__[self.name] = self.func(instance)
  File "/usr/local/lib/python3.5/site-packages/django/urls/resolvers.py", line 536, in url_patterns
    patterns = getattr(self.urlconf_module, "urlpatterns", self.urlconf_module)
  File "/usr/local/lib/python3.5/site-packages/django/utils/functional.py", line 36, in __get__
    res = instance.__dict__[self.name] = self.func(instance)
  File "/usr/local/lib/python3.5/site-packages/django/urls/resolvers.py", line 529, in urlconf_module
    return import_module(self.urlconf_name)
  File "/usr/local/lib/python3.5/importlib/__init__.py", line 126, in import_module
    return _bootstrap._gcd_import(name[level:], package, level)
  File "<frozen importlib._bootstrap>", line 985, in _gcd_import
  File "<frozen importlib._bootstrap>", line 968, in _find_and_load
  File "<frozen importlib._bootstrap>", line 957, in _find_and_load_unlocked
  File "<frozen importlib._bootstrap>", line 673, in _load_unlocked
  File "<frozen importlib._bootstrap_external>", line 697, in exec_module
  File "<frozen importlib._bootstrap>", line 222, in _call_with_frames_removed
  File "/home/django_app/project/urls.py", line 29, in <module>
    ] + static(settings.MEDIA_URL, document_root=settings.MEDIA_ROOT)
NameError: name 'static' is not defined
[2018-09-21 21:48:44 +0000] [15] [CRITICAL] WORKER TIMEOUT (pid:37)
[2018-09-21 16:48:44 -0500] [37] [INFO] Worker exiting (pid: 37)
[2018-09-21 21:48:44 +0000] [60] [INFO] Booting worker with pid: 60
[2018-09-21 16:55:27 -0500] [35] [INFO] Worker reloading: /home/django_app/c_olimpo/models.py modified
[2018-09-21 16:55:27 -0500] [35] [INFO] Worker exiting (pid: 35)
[2018-09-21 16:55:27 -0500] [60] [INFO] Worker reloading: /home/django_app/c_olimpo/models.py modified
[2018-09-21 16:55:27 -0500] [60] [INFO] Worker exiting (pid: 60)
[2018-09-21 21:55:27 +0000] [63] [INFO] Booting worker with pid: 63
[2018-09-21 21:55:27 +0000] [66] [INFO] Booting worker with pid: 66
[2018-09-21 21:59:10 +0000] [15] [CRITICAL] WORKER TIMEOUT (pid:66)
[2018-09-21 21:59:10 +0000] [15] [CRITICAL] WORKER TIMEOUT (pid:63)
[2018-09-21 16:59:10 -0500] [66] [INFO] Worker exiting (pid: 66)
[2018-09-21 16:59:10 -0500] [63] [INFO] Worker exiting (pid: 63)
[2018-09-21 21:59:10 +0000] [69] [INFO] Booting worker with pid: 69
[2018-09-21 21:59:10 +0000] [71] [INFO] Booting worker with pid: 71
[2018-09-21 17:00:16 -0500] [69] [INFO] Worker reloading: /home/django_app/c_olimpo/models.py modified
[2018-09-21 17:00:16 -0500] [71] [INFO] Worker reloading: /home/django_app/c_olimpo/models.py modified
[2018-09-21 17:00:16 -0500] [69] [INFO] Worker exiting (pid: 69)
[2018-09-21 17:00:16 -0500] [71] [INFO] Worker exiting (pid: 71)
[2018-09-21 22:00:16 +0000] [75] [INFO] Booting worker with pid: 75
[2018-09-21 22:00:16 +0000] [78] [INFO] Booting worker with pid: 78
Not Found: /media/A104.pdf
[2018-09-21 22:01:51 +0000] [15] [CRITICAL] WORKER TIMEOUT (pid:78)
[2018-09-21 17:01:51 -0500] [78] [INFO] Worker exiting (pid: 78)
[2018-09-21 22:01:52 +0000] [81] [INFO] Booting worker with pid: 81
[2018-09-21 22:33:02 +0000] [15] [CRITICAL] WORKER TIMEOUT (pid:81)
[2018-09-21 22:33:02 +0000] [15] [CRITICAL] WORKER TIMEOUT (pid:75)
[2018-09-21 17:33:02 -0500] [75] [INFO] Worker exiting (pid: 75)
[2018-09-21 17:33:02 -0500] [81] [INFO] Worker exiting (pid: 81)
[2018-09-21 22:33:02 +0000] [84] [INFO] Booting worker with pid: 84
[2018-09-21 22:33:02 +0000] [86] [INFO] Booting worker with pid: 86
[2018-09-21 22:39:47 +0000] [17] [INFO] Starting gunicorn 19.5.0
[2018-09-21 22:39:47 +0000] [17] [INFO] Listening at: http://0.0.0.0:9000 (17)
[2018-09-21 22:39:47 +0000] [17] [INFO] Using worker: sync
[2018-09-21 22:39:47 +0000] [20] [INFO] Booting worker with pid: 20
[2018-09-21 22:39:47 +0000] [23] [INFO] Booting worker with pid: 23
[2018-09-21 22:40:24 +0000] [17] [CRITICAL] WORKER TIMEOUT (pid:20)
[2018-09-21 22:40:24 +0000] [17] [CRITICAL] WORKER TIMEOUT (pid:23)
[2018-09-21 17:40:24 -0500] [20] [INFO] Worker exiting (pid: 20)
[2018-09-21 17:40:24 -0500] [23] [INFO] Worker exiting (pid: 23)
[2018-09-21 22:40:24 +0000] [26] [INFO] Booting worker with pid: 26
[2018-09-21 22:40:24 +0000] [28] [INFO] Booting worker with pid: 28
Not Found: /media/A101.pdf
[2018-09-21 22:42:24 +0000] [17] [CRITICAL] WORKER TIMEOUT (pid:26)
[2018-09-21 22:42:24 +0000] [17] [CRITICAL] WORKER TIMEOUT (pid:28)
[2018-09-21 17:42:24 -0500] [28] [INFO] Worker exiting (pid: 28)
[2018-09-21 22:42:25 +0000] [40] [INFO] Booting worker with pid: 40
[2018-09-21 22:42:25 +0000] [42] [INFO] Booting worker with pid: 42
[2018-09-21 22:44:03 +0000] [17] [CRITICAL] WORKER TIMEOUT (pid:40)
[2018-09-21 22:44:03 +0000] [17] [CRITICAL] WORKER TIMEOUT (pid:42)
[2018-09-21 17:44:03 -0500] [40] [INFO] Worker exiting (pid: 40)
[2018-09-21 22:44:03 +0000] [53] [INFO] Booting worker with pid: 53
[2018-09-21 22:44:03 +0000] [55] [INFO] Booting worker with pid: 55
[2018-09-21 22:46:49 +0000] [17] [CRITICAL] WORKER TIMEOUT (pid:53)
[2018-09-21 22:46:49 +0000] [17] [CRITICAL] WORKER TIMEOUT (pid:55)
[2018-09-21 17:46:49 -0500] [55] [INFO] Worker exiting (pid: 55)
[2018-09-21 22:46:49 +0000] [71] [INFO] Booting worker with pid: 71
[2018-09-21 22:46:50 +0000] [73] [INFO] Booting worker with pid: 73
[2018-09-21 22:51:02 +0000] [17] [CRITICAL] WORKER TIMEOUT (pid:73)
[2018-09-21 22:51:02 +0000] [17] [CRITICAL] WORKER TIMEOUT (pid:71)
[2018-09-21 17:51:02 -0500] [71] [INFO] Worker exiting (pid: 71)
[2018-09-21 22:51:02 +0000] [116] [INFO] Booting worker with pid: 116
[2018-09-21 22:51:02 +0000] [118] [INFO] Booting worker with pid: 118
[2018-09-21 17:58:04 -0500] [116] [INFO] Worker reloading: /home/django_app/c_olimpo/admin.py modified
[2018-09-21 17:58:04 -0500] [118] [INFO] Worker reloading: /home/django_app/c_olimpo/admin.py modified
[2018-09-21 17:58:04 -0500] [116] [INFO] Worker reloading: /home/django_app/c_olimpo/models.py modified
[2018-09-21 17:58:04 -0500] [118] [INFO] Worker reloading: /home/django_app/c_olimpo/models.py modified
[2018-09-21 17:58:04 -0500] [116] [INFO] Worker exiting (pid: 116)
[2018-09-21 17:58:04 -0500] [118] [INFO] Worker exiting (pid: 118)
[2018-09-21 22:58:04 +0000] [135] [INFO] Booting worker with pid: 135
[2018-09-21 22:58:04 +0000] [137] [INFO] Booting worker with pid: 137
[2018-09-21 23:01:54 +0000] [17] [INFO] Starting gunicorn 19.5.0
[2018-09-21 23:01:54 +0000] [17] [INFO] Listening at: http://0.0.0.0:9000 (17)
[2018-09-21 23:01:54 +0000] [17] [INFO] Using worker: sync
[2018-09-21 23:01:54 +0000] [20] [INFO] Booting worker with pid: 20
[2018-09-21 23:01:54 +0000] [22] [INFO] Booting worker with pid: 22
[2018-09-21 23:19:58 +0000] [15] [INFO] Starting gunicorn 19.5.0
[2018-09-21 23:19:58 +0000] [15] [INFO] Listening at: http://0.0.0.0:9000 (15)
[2018-09-21 23:19:58 +0000] [15] [INFO] Using worker: sync
[2018-09-21 23:19:58 +0000] [18] [INFO] Booting worker with pid: 18
[2018-09-21 23:19:58 +0000] [21] [INFO] Booting worker with pid: 21
[2018-09-21 18:42:14 -0500] [18] [INFO] Worker reloading: /home/django_app/project/settings.py modified
[2018-09-21 18:42:14 -0500] [21] [INFO] Worker reloading: /home/django_app/project/settings.py modified
[2018-09-21 18:42:15 -0500] [18] [INFO] Worker exiting (pid: 18)
[2018-09-21 18:42:15 -0500] [21] [INFO] Worker exiting (pid: 21)
[2018-09-21 23:42:15 +0000] [24] [INFO] Booting worker with pid: 24
[2018-09-21 23:42:15 +0000] [26] [INFO] Booting worker with pid: 26
[2018-09-21 23:42:15 +0000] [26] [ERROR] invalid syntax (settings.py, line 157)
Traceback (most recent call last):
  File "/usr/local/lib/python3.5/site-packages/gunicorn/workers/base.py", line 132, in load_wsgi
    self.wsgi = self.app.wsgi()
  File "/usr/local/lib/python3.5/site-packages/gunicorn/app/base.py", line 67, in wsgi
    self.callable = self.load()
  File "/usr/local/lib/python3.5/site-packages/gunicorn/app/wsgiapp.py", line 65, in load
    return self.load_wsgiapp()
  File "/usr/local/lib/python3.5/site-packages/gunicorn/app/wsgiapp.py", line 52, in load_wsgiapp
    return util.import_app(self.app_uri)
  File "/usr/local/lib/python3.5/site-packages/gunicorn/util.py", line 357, in import_app
    __import__(module)
  File "/home/django_app/wsgi.py", line 16, in <module>
    application = get_wsgi_application()
  File "/usr/local/lib/python3.5/site-packages/django/core/wsgi.py", line 12, in get_wsgi_application
    django.setup(set_prefix=False)
  File "/usr/local/lib/python3.5/site-packages/django/__init__.py", line 19, in setup
    configure_logging(settings.LOGGING_CONFIG, settings.LOGGING)
  File "/usr/local/lib/python3.5/site-packages/django/conf/__init__.py", line 56, in __getattr__
    self._setup(name)
  File "/usr/local/lib/python3.5/site-packages/django/conf/__init__.py", line 43, in _setup
    self._wrapped = Settings(settings_module)
  File "/usr/local/lib/python3.5/site-packages/django/conf/__init__.py", line 106, in __init__
    mod = importlib.import_module(self.SETTINGS_MODULE)
  File "/usr/local/lib/python3.5/importlib/__init__.py", line 126, in import_module
    return _bootstrap._gcd_import(name[level:], package, level)
  File "/home/django_app/project/settings.py", line 157
    MEDIA_ROOT  = '/tmp')
                        ^
SyntaxError: invalid syntax
[2018-09-21 23:42:15 +0000] [24] [ERROR] invalid syntax (settings.py, line 157)
Traceback (most recent call last):
  File "/usr/local/lib/python3.5/site-packages/gunicorn/workers/base.py", line 132, in load_wsgi
    self.wsgi = self.app.wsgi()
  File "/usr/local/lib/python3.5/site-packages/gunicorn/app/base.py", line 67, in wsgi
    self.callable = self.load()
  File "/usr/local/lib/python3.5/site-packages/gunicorn/app/wsgiapp.py", line 65, in load
    return self.load_wsgiapp()
  File "/usr/local/lib/python3.5/site-packages/gunicorn/app/wsgiapp.py", line 52, in load_wsgiapp
    return util.import_app(self.app_uri)
  File "/usr/local/lib/python3.5/site-packages/gunicorn/util.py", line 357, in import_app
    __import__(module)
  File "/home/django_app/wsgi.py", line 16, in <module>
    application = get_wsgi_application()
  File "/usr/local/lib/python3.5/site-packages/django/core/wsgi.py", line 12, in get_wsgi_application
    django.setup(set_prefix=False)
  File "/usr/local/lib/python3.5/site-packages/django/__init__.py", line 19, in setup
    configure_logging(settings.LOGGING_CONFIG, settings.LOGGING)
  File "/usr/local/lib/python3.5/site-packages/django/conf/__init__.py", line 56, in __getattr__
    self._setup(name)
  File "/usr/local/lib/python3.5/site-packages/django/conf/__init__.py", line 43, in _setup
    self._wrapped = Settings(settings_module)
  File "/usr/local/lib/python3.5/site-packages/django/conf/__init__.py", line 106, in __init__
    mod = importlib.import_module(self.SETTINGS_MODULE)
  File "/usr/local/lib/python3.5/importlib/__init__.py", line 126, in import_module
    return _bootstrap._gcd_import(name[level:], package, level)
  File "/home/django_app/project/settings.py", line 157
    MEDIA_ROOT  = '/tmp')
                        ^
SyntaxError: invalid syntax
[2018-09-21 23:43:35 +0000] [16] [INFO] Starting gunicorn 19.5.0
[2018-09-21 23:43:35 +0000] [16] [INFO] Listening at: http://0.0.0.0:9000 (16)
[2018-09-21 23:43:35 +0000] [16] [INFO] Using worker: sync
[2018-09-21 23:43:35 +0000] [19] [INFO] Booting worker with pid: 19
[2018-09-21 23:43:35 +0000] [21] [INFO] Booting worker with pid: 21
[2018-09-21 23:43:36 +0000] [21] [ERROR] invalid syntax (settings.py, line 157)
Traceback (most recent call last):
  File "/usr/local/lib/python3.5/site-packages/gunicorn/workers/base.py", line 132, in load_wsgi
    self.wsgi = self.app.wsgi()
  File "/usr/local/lib/python3.5/site-packages/gunicorn/app/base.py", line 67, in wsgi
    self.callable = self.load()
  File "/usr/local/lib/python3.5/site-packages/gunicorn/app/wsgiapp.py", line 65, in load
    return self.load_wsgiapp()
  File "/usr/local/lib/python3.5/site-packages/gunicorn/app/wsgiapp.py", line 52, in load_wsgiapp
    return util.import_app(self.app_uri)
  File "/usr/local/lib/python3.5/site-packages/gunicorn/util.py", line 357, in import_app
    __import__(module)
  File "/home/django_app/wsgi.py", line 16, in <module>
    application = get_wsgi_application()
  File "/usr/local/lib/python3.5/site-packages/django/core/wsgi.py", line 12, in get_wsgi_application
    django.setup(set_prefix=False)
  File "/usr/local/lib/python3.5/site-packages/django/__init__.py", line 19, in setup
    configure_logging(settings.LOGGING_CONFIG, settings.LOGGING)
  File "/usr/local/lib/python3.5/site-packages/django/conf/__init__.py", line 56, in __getattr__
    self._setup(name)
  File "/usr/local/lib/python3.5/site-packages/django/conf/__init__.py", line 43, in _setup
    self._wrapped = Settings(settings_module)
  File "/usr/local/lib/python3.5/site-packages/django/conf/__init__.py", line 106, in __init__
    mod = importlib.import_module(self.SETTINGS_MODULE)
  File "/usr/local/lib/python3.5/importlib/__init__.py", line 126, in import_module
    return _bootstrap._gcd_import(name[level:], package, level)
  File "/home/django_app/project/settings.py", line 157
    MEDIA_ROOT  = '/tmp')
                        ^
SyntaxError: invalid syntax
[2018-09-21 23:43:36 +0000] [19] [ERROR] invalid syntax (settings.py, line 157)
Traceback (most recent call last):
  File "/usr/local/lib/python3.5/site-packages/gunicorn/workers/base.py", line 132, in load_wsgi
    self.wsgi = self.app.wsgi()
  File "/usr/local/lib/python3.5/site-packages/gunicorn/app/base.py", line 67, in wsgi
    self.callable = self.load()
  File "/usr/local/lib/python3.5/site-packages/gunicorn/app/wsgiapp.py", line 65, in load
    return self.load_wsgiapp()
  File "/usr/local/lib/python3.5/site-packages/gunicorn/app/wsgiapp.py", line 52, in load_wsgiapp
    return util.import_app(self.app_uri)
  File "/usr/local/lib/python3.5/site-packages/gunicorn/util.py", line 357, in import_app
    __import__(module)
  File "/home/django_app/wsgi.py", line 16, in <module>
    application = get_wsgi_application()
  File "/usr/local/lib/python3.5/site-packages/django/core/wsgi.py", line 12, in get_wsgi_application
    django.setup(set_prefix=False)
  File "/usr/local/lib/python3.5/site-packages/django/__init__.py", line 19, in setup
    configure_logging(settings.LOGGING_CONFIG, settings.LOGGING)
  File "/usr/local/lib/python3.5/site-packages/django/conf/__init__.py", line 56, in __getattr__
    self._setup(name)
  File "/usr/local/lib/python3.5/site-packages/django/conf/__init__.py", line 43, in _setup
    self._wrapped = Settings(settings_module)
  File "/usr/local/lib/python3.5/site-packages/django/conf/__init__.py", line 106, in __init__
    mod = importlib.import_module(self.SETTINGS_MODULE)
  File "/usr/local/lib/python3.5/importlib/__init__.py", line 126, in import_module
    return _bootstrap._gcd_import(name[level:], package, level)
  File "/home/django_app/project/settings.py", line 157
    MEDIA_ROOT  = '/tmp')
                        ^
SyntaxError: invalid syntax
[2018-09-21 23:44:20 +0000] [19] [ERROR] Error handling request
Traceback (most recent call last):
  File "/usr/local/lib/python3.5/site-packages/gunicorn/workers/sync.py", line 180, in handle_request
    resp.write(item)
  File "/usr/local/lib/python3.5/site-packages/gunicorn/http/wsgi.py", line 344, in write
    raise TypeError('%r is not a byte' % arg)
TypeError: ['  File "/usr/local/lib/python3.5/site-packages/gunicorn/workers/base.py", line 132, in load_wsgi\n    self.wsgi = self.app.wsgi()\n', '  File "/usr/local/lib/python3.5/site-packages/gunicorn/app/base.py", line 67, in wsgi\n    self.callable = self.load()\n', '  File "/usr/local/lib/python3.5/site-packages/gunicorn/app/wsgiapp.py", line 65, in load\n    return self.load_wsgiapp()\n', '  File "/usr/local/lib/python3.5/site-packages/gunicorn/app/wsgiapp.py", line 52, in load_wsgiapp\n    return util.import_app(self.app_uri)\n', '  File "/usr/local/lib/python3.5/site-packages/gunicorn/util.py", line 357, in import_app\n    __import__(module)\n', '  File "/home/django_app/wsgi.py", line 16, in <module>\n    application = get_wsgi_application()\n', '  File "/usr/local/lib/python3.5/site-packages/django/core/wsgi.py", line 12, in get_wsgi_application\n    django.setup(set_prefix=False)\n', '  File "/usr/local/lib/python3.5/site-packages/django/__init__.py", line 19, in setup\n    configure_logging(settings.LOGGING_CONFIG, settings.LOGGING)\n', '  File "/usr/local/lib/python3.5/site-packages/django/conf/__init__.py", line 56, in __getattr__\n    self._setup(name)\n', '  File "/usr/local/lib/python3.5/site-packages/django/conf/__init__.py", line 43, in _setup\n    self._wrapped = Settings(settings_module)\n', '  File "/usr/local/lib/python3.5/site-packages/django/conf/__init__.py", line 106, in __init__\n    mod = importlib.import_module(self.SETTINGS_MODULE)\n', '  File "/usr/local/lib/python3.5/importlib/__init__.py", line 126, in import_module\n    return _bootstrap._gcd_import(name[level:], package, level)\n'] is not a byte
[2018-09-21 23:44:21 +0000] [21] [ERROR] Error handling request
Traceback (most recent call last):
  File "/usr/local/lib/python3.5/site-packages/gunicorn/workers/sync.py", line 180, in handle_request
    resp.write(item)
  File "/usr/local/lib/python3.5/site-packages/gunicorn/http/wsgi.py", line 344, in write
    raise TypeError('%r is not a byte' % arg)
TypeError: ['  File "/usr/local/lib/python3.5/site-packages/gunicorn/workers/base.py", line 132, in load_wsgi\n    self.wsgi = self.app.wsgi()\n', '  File "/usr/local/lib/python3.5/site-packages/gunicorn/app/base.py", line 67, in wsgi\n    self.callable = self.load()\n', '  File "/usr/local/lib/python3.5/site-packages/gunicorn/app/wsgiapp.py", line 65, in load\n    return self.load_wsgiapp()\n', '  File "/usr/local/lib/python3.5/site-packages/gunicorn/app/wsgiapp.py", line 52, in load_wsgiapp\n    return util.import_app(self.app_uri)\n', '  File "/usr/local/lib/python3.5/site-packages/gunicorn/util.py", line 357, in import_app\n    __import__(module)\n', '  File "/home/django_app/wsgi.py", line 16, in <module>\n    application = get_wsgi_application()\n', '  File "/usr/local/lib/python3.5/site-packages/django/core/wsgi.py", line 12, in get_wsgi_application\n    django.setup(set_prefix=False)\n', '  File "/usr/local/lib/python3.5/site-packages/django/__init__.py", line 19, in setup\n    configure_logging(settings.LOGGING_CONFIG, settings.LOGGING)\n', '  File "/usr/local/lib/python3.5/site-packages/django/conf/__init__.py", line 56, in __getattr__\n    self._setup(name)\n', '  File "/usr/local/lib/python3.5/site-packages/django/conf/__init__.py", line 43, in _setup\n    self._wrapped = Settings(settings_module)\n', '  File "/usr/local/lib/python3.5/site-packages/django/conf/__init__.py", line 106, in __init__\n    mod = importlib.import_module(self.SETTINGS_MODULE)\n', '  File "/usr/local/lib/python3.5/importlib/__init__.py", line 126, in import_module\n    return _bootstrap._gcd_import(name[level:], package, level)\n'] is not a byte
[2018-09-21 23:44:22 +0000] [19] [ERROR] Error handling request
Traceback (most recent call last):
  File "/usr/local/lib/python3.5/site-packages/gunicorn/workers/sync.py", line 180, in handle_request
    resp.write(item)
  File "/usr/local/lib/python3.5/site-packages/gunicorn/http/wsgi.py", line 344, in write
    raise TypeError('%r is not a byte' % arg)
TypeError: ['  File "/usr/local/lib/python3.5/site-packages/gunicorn/workers/base.py", line 132, in load_wsgi\n    self.wsgi = self.app.wsgi()\n', '  File "/usr/local/lib/python3.5/site-packages/gunicorn/app/base.py", line 67, in wsgi\n    self.callable = self.load()\n', '  File "/usr/local/lib/python3.5/site-packages/gunicorn/app/wsgiapp.py", line 65, in load\n    return self.load_wsgiapp()\n', '  File "/usr/local/lib/python3.5/site-packages/gunicorn/app/wsgiapp.py", line 52, in load_wsgiapp\n    return util.import_app(self.app_uri)\n', '  File "/usr/local/lib/python3.5/site-packages/gunicorn/util.py", line 357, in import_app\n    __import__(module)\n', '  File "/home/django_app/wsgi.py", line 16, in <module>\n    application = get_wsgi_application()\n', '  File "/usr/local/lib/python3.5/site-packages/django/core/wsgi.py", line 12, in get_wsgi_application\n    django.setup(set_prefix=False)\n', '  File "/usr/local/lib/python3.5/site-packages/django/__init__.py", line 19, in setup\n    configure_logging(settings.LOGGING_CONFIG, settings.LOGGING)\n', '  File "/usr/local/lib/python3.5/site-packages/django/conf/__init__.py", line 56, in __getattr__\n    self._setup(name)\n', '  File "/usr/local/lib/python3.5/site-packages/django/conf/__init__.py", line 43, in _setup\n    self._wrapped = Settings(settings_module)\n', '  File "/usr/local/lib/python3.5/site-packages/django/conf/__init__.py", line 106, in __init__\n    mod = importlib.import_module(self.SETTINGS_MODULE)\n', '  File "/usr/local/lib/python3.5/importlib/__init__.py", line 126, in import_module\n    return _bootstrap._gcd_import(name[level:], package, level)\n'] is not a byte
[2018-09-21 23:44:29 +0000] [21] [ERROR] Error handling request
Traceback (most recent call last):
  File "/usr/local/lib/python3.5/site-packages/gunicorn/workers/sync.py", line 180, in handle_request
    resp.write(item)
  File "/usr/local/lib/python3.5/site-packages/gunicorn/http/wsgi.py", line 344, in write
    raise TypeError('%r is not a byte' % arg)
TypeError: ['  File "/usr/local/lib/python3.5/site-packages/gunicorn/workers/base.py", line 132, in load_wsgi\n    self.wsgi = self.app.wsgi()\n', '  File "/usr/local/lib/python3.5/site-packages/gunicorn/app/base.py", line 67, in wsgi\n    self.callable = self.load()\n', '  File "/usr/local/lib/python3.5/site-packages/gunicorn/app/wsgiapp.py", line 65, in load\n    return self.load_wsgiapp()\n', '  File "/usr/local/lib/python3.5/site-packages/gunicorn/app/wsgiapp.py", line 52, in load_wsgiapp\n    return util.import_app(self.app_uri)\n', '  File "/usr/local/lib/python3.5/site-packages/gunicorn/util.py", line 357, in import_app\n    __import__(module)\n', '  File "/home/django_app/wsgi.py", line 16, in <module>\n    application = get_wsgi_application()\n', '  File "/usr/local/lib/python3.5/site-packages/django/core/wsgi.py", line 12, in get_wsgi_application\n    django.setup(set_prefix=False)\n', '  File "/usr/local/lib/python3.5/site-packages/django/__init__.py", line 19, in setup\n    configure_logging(settings.LOGGING_CONFIG, settings.LOGGING)\n', '  File "/usr/local/lib/python3.5/site-packages/django/conf/__init__.py", line 56, in __getattr__\n    self._setup(name)\n', '  File "/usr/local/lib/python3.5/site-packages/django/conf/__init__.py", line 43, in _setup\n    self._wrapped = Settings(settings_module)\n', '  File "/usr/local/lib/python3.5/site-packages/django/conf/__init__.py", line 106, in __init__\n    mod = importlib.import_module(self.SETTINGS_MODULE)\n', '  File "/usr/local/lib/python3.5/importlib/__init__.py", line 126, in import_module\n    return _bootstrap._gcd_import(name[level:], package, level)\n'] is not a byte
[2018-09-21 23:44:51 +0000] [21] [ERROR] Error handling request
Traceback (most recent call last):
  File "/usr/local/lib/python3.5/site-packages/gunicorn/workers/sync.py", line 180, in handle_request
    resp.write(item)
  File "/usr/local/lib/python3.5/site-packages/gunicorn/http/wsgi.py", line 344, in write
    raise TypeError('%r is not a byte' % arg)
TypeError: ['  File "/usr/local/lib/python3.5/site-packages/gunicorn/workers/base.py", line 132, in load_wsgi\n    self.wsgi = self.app.wsgi()\n', '  File "/usr/local/lib/python3.5/site-packages/gunicorn/app/base.py", line 67, in wsgi\n    self.callable = self.load()\n', '  File "/usr/local/lib/python3.5/site-packages/gunicorn/app/wsgiapp.py", line 65, in load\n    return self.load_wsgiapp()\n', '  File "/usr/local/lib/python3.5/site-packages/gunicorn/app/wsgiapp.py", line 52, in load_wsgiapp\n    return util.import_app(self.app_uri)\n', '  File "/usr/local/lib/python3.5/site-packages/gunicorn/util.py", line 357, in import_app\n    __import__(module)\n', '  File "/home/django_app/wsgi.py", line 16, in <module>\n    application = get_wsgi_application()\n', '  File "/usr/local/lib/python3.5/site-packages/django/core/wsgi.py", line 12, in get_wsgi_application\n    django.setup(set_prefix=False)\n', '  File "/usr/local/lib/python3.5/site-packages/django/__init__.py", line 19, in setup\n    configure_logging(settings.LOGGING_CONFIG, settings.LOGGING)\n', '  File "/usr/local/lib/python3.5/site-packages/django/conf/__init__.py", line 56, in __getattr__\n    self._setup(name)\n', '  File "/usr/local/lib/python3.5/site-packages/django/conf/__init__.py", line 43, in _setup\n    self._wrapped = Settings(settings_module)\n', '  File "/usr/local/lib/python3.5/site-packages/django/conf/__init__.py", line 106, in __init__\n    mod = importlib.import_module(self.SETTINGS_MODULE)\n', '  File "/usr/local/lib/python3.5/importlib/__init__.py", line 126, in import_module\n    return _bootstrap._gcd_import(name[level:], package, level)\n'] is not a byte
[2018-09-21 23:44:53 +0000] [21] [ERROR] Error handling request
Traceback (most recent call last):
  File "/usr/local/lib/python3.5/site-packages/gunicorn/workers/sync.py", line 180, in handle_request
    resp.write(item)
  File "/usr/local/lib/python3.5/site-packages/gunicorn/http/wsgi.py", line 344, in write
    raise TypeError('%r is not a byte' % arg)
TypeError: ['  File "/usr/local/lib/python3.5/site-packages/gunicorn/workers/base.py", line 132, in load_wsgi\n    self.wsgi = self.app.wsgi()\n', '  File "/usr/local/lib/python3.5/site-packages/gunicorn/app/base.py", line 67, in wsgi\n    self.callable = self.load()\n', '  File "/usr/local/lib/python3.5/site-packages/gunicorn/app/wsgiapp.py", line 65, in load\n    return self.load_wsgiapp()\n', '  File "/usr/local/lib/python3.5/site-packages/gunicorn/app/wsgiapp.py", line 52, in load_wsgiapp\n    return util.import_app(self.app_uri)\n', '  File "/usr/local/lib/python3.5/site-packages/gunicorn/util.py", line 357, in import_app\n    __import__(module)\n', '  File "/home/django_app/wsgi.py", line 16, in <module>\n    application = get_wsgi_application()\n', '  File "/usr/local/lib/python3.5/site-packages/django/core/wsgi.py", line 12, in get_wsgi_application\n    django.setup(set_prefix=False)\n', '  File "/usr/local/lib/python3.5/site-packages/django/__init__.py", line 19, in setup\n    configure_logging(settings.LOGGING_CONFIG, settings.LOGGING)\n', '  File "/usr/local/lib/python3.5/site-packages/django/conf/__init__.py", line 56, in __getattr__\n    self._setup(name)\n', '  File "/usr/local/lib/python3.5/site-packages/django/conf/__init__.py", line 43, in _setup\n    self._wrapped = Settings(settings_module)\n', '  File "/usr/local/lib/python3.5/site-packages/django/conf/__init__.py", line 106, in __init__\n    mod = importlib.import_module(self.SETTINGS_MODULE)\n', '  File "/usr/local/lib/python3.5/importlib/__init__.py", line 126, in import_module\n    return _bootstrap._gcd_import(name[level:], package, level)\n'] is not a byte
[2018-09-21 23:45:22 +0000] [16] [CRITICAL] WORKER TIMEOUT (pid:19)
[2018-09-21 23:45:22 +0000] [19] [INFO] Worker exiting (pid: 19)
[2018-09-21 23:45:22 +0000] [25] [INFO] Booting worker with pid: 25
[2018-09-21 23:45:22 +0000] [25] [ERROR] invalid syntax (settings.py, line 157)
Traceback (most recent call last):
  File "/usr/local/lib/python3.5/site-packages/gunicorn/workers/base.py", line 132, in load_wsgi
    self.wsgi = self.app.wsgi()
  File "/usr/local/lib/python3.5/site-packages/gunicorn/app/base.py", line 67, in wsgi
    self.callable = self.load()
  File "/usr/local/lib/python3.5/site-packages/gunicorn/app/wsgiapp.py", line 65, in load
    return self.load_wsgiapp()
  File "/usr/local/lib/python3.5/site-packages/gunicorn/app/wsgiapp.py", line 52, in load_wsgiapp
    return util.import_app(self.app_uri)
  File "/usr/local/lib/python3.5/site-packages/gunicorn/util.py", line 357, in import_app
    __import__(module)
  File "/home/django_app/wsgi.py", line 16, in <module>
    application = get_wsgi_application()
  File "/usr/local/lib/python3.5/site-packages/django/core/wsgi.py", line 12, in get_wsgi_application
    django.setup(set_prefix=False)
  File "/usr/local/lib/python3.5/site-packages/django/__init__.py", line 19, in setup
    configure_logging(settings.LOGGING_CONFIG, settings.LOGGING)
  File "/usr/local/lib/python3.5/site-packages/django/conf/__init__.py", line 56, in __getattr__
    self._setup(name)
  File "/usr/local/lib/python3.5/site-packages/django/conf/__init__.py", line 43, in _setup
    self._wrapped = Settings(settings_module)
  File "/usr/local/lib/python3.5/site-packages/django/conf/__init__.py", line 106, in __init__
    mod = importlib.import_module(self.SETTINGS_MODULE)
  File "/usr/local/lib/python3.5/importlib/__init__.py", line 126, in import_module
    return _bootstrap._gcd_import(name[level:], package, level)
  File "/home/django_app/project/settings.py", line 157
    MEDIA_ROOT  = '/tmp')
                        ^
SyntaxError: invalid syntax
[2018-09-21 23:46:41 +0000] [25] [INFO] Worker reloading: /home/django_app/project/settings.py modified
[2018-09-21 23:46:41 +0000] [25] [INFO] Worker exiting (pid: 25)
[2018-09-21 23:46:41 +0000] [36] [INFO] Booting worker with pid: 36
[2018-09-21 23:46:41 +0000] [21] [INFO] Worker reloading: /home/django_app/project/settings.py modified
[2018-09-21 23:46:41 +0000] [21] [INFO] Worker exiting (pid: 21)
[2018-09-21 23:46:41 +0000] [39] [INFO] Booting worker with pid: 39
Not Found: /media/A101.pdf
[2018-09-21 23:50:19 +0000] [16] [CRITICAL] WORKER TIMEOUT (pid:39)
[2018-09-21 18:50:19 -0500] [39] [INFO] Worker exiting (pid: 39)
[2018-09-21 23:50:19 +0000] [48] [INFO] Booting worker with pid: 48
[2018-09-21 23:50:21 +0000] [16] [CRITICAL] WORKER TIMEOUT (pid:36)
[2018-09-21 18:50:21 -0500] [36] [INFO] Worker exiting (pid: 36)
[2018-09-21 23:50:21 +0000] [51] [INFO] Booting worker with pid: 51
[2018-09-21 23:50:50 +0000] [16] [CRITICAL] WORKER TIMEOUT (pid:48)
[2018-09-21 18:50:50 -0500] [48] [INFO] Worker exiting (pid: 48)
[2018-09-21 23:50:50 +0000] [54] [INFO] Booting worker with pid: 54
[2018-09-21 23:52:50 +0000] [16] [CRITICAL] WORKER TIMEOUT (pid:51)
[2018-09-21 23:52:50 +0000] [16] [CRITICAL] WORKER TIMEOUT (pid:54)
[2018-09-21 18:52:50 -0500] [51] [INFO] Worker exiting (pid: 51)
[2018-09-21 23:52:50 +0000] [60] [INFO] Booting worker with pid: 60
[2018-09-21 23:52:50 +0000] [62] [INFO] Booting worker with pid: 62
[2018-09-21 23:54:44 +0000] [16] [CRITICAL] WORKER TIMEOUT (pid:60)
[2018-09-21 23:54:44 +0000] [16] [CRITICAL] WORKER TIMEOUT (pid:62)
[2018-09-21 18:54:44 -0500] [62] [INFO] Worker exiting (pid: 62)
[2018-09-21 23:54:44 +0000] [83] [INFO] Booting worker with pid: 83
[2018-09-21 23:54:44 +0000] [85] [INFO] Booting worker with pid: 85
[2018-09-21 23:58:33 +0000] [16] [CRITICAL] WORKER TIMEOUT (pid:83)
[2018-09-21 23:58:33 +0000] [16] [CRITICAL] WORKER TIMEOUT (pid:85)
[2018-09-21 18:58:33 -0500] [85] [INFO] Worker exiting (pid: 85)
[2018-09-21 23:58:34 +0000] [102] [INFO] Booting worker with pid: 102
[2018-09-21 23:58:34 +0000] [104] [INFO] Booting worker with pid: 104
[2018-09-22 00:01:00 +0000] [16] [CRITICAL] WORKER TIMEOUT (pid:104)
[2018-09-22 00:01:00 +0000] [16] [CRITICAL] WORKER TIMEOUT (pid:102)
[2018-09-21 19:01:00 -0500] [104] [INFO] Worker exiting (pid: 104)
[2018-09-21 19:01:00 -0500] [102] [INFO] Worker exiting (pid: 102)
[2018-09-22 00:01:00 +0000] [111] [INFO] Booting worker with pid: 111
[2018-09-22 00:01:00 +0000] [114] [INFO] Booting worker with pid: 114
[2018-09-22 00:01:31 +0000] [16] [CRITICAL] WORKER TIMEOUT (pid:114)
[2018-09-22 00:01:31 +0000] [16] [CRITICAL] WORKER TIMEOUT (pid:111)
[2018-09-21 19:01:31 -0500] [114] [INFO] Worker exiting (pid: 114)
[2018-09-21 19:01:31 -0500] [111] [INFO] Worker exiting (pid: 111)
[2018-09-22 00:01:32 +0000] [117] [INFO] Booting worker with pid: 117
[2018-09-22 00:01:32 +0000] [119] [INFO] Booting worker with pid: 119
[2018-09-22 00:02:03 +0000] [16] [CRITICAL] WORKER TIMEOUT (pid:117)
[2018-09-22 00:02:03 +0000] [16] [CRITICAL] WORKER TIMEOUT (pid:119)
[2018-09-21 19:02:03 -0500] [119] [INFO] Worker exiting (pid: 119)
[2018-09-22 00:02:03 +0000] [126] [INFO] Booting worker with pid: 126
[2018-09-22 00:02:03 +0000] [129] [INFO] Booting worker with pid: 129
[2018-09-21 19:09:44 -0500] [129] [INFO] Worker reloading: /home/django_app/c_olimpo/admin.py modified
[2018-09-21 19:09:44 -0500] [126] [INFO] Worker reloading: /home/django_app/c_olimpo/admin.py modified
[2018-09-21 19:09:44 -0500] [129] [INFO] Worker exiting (pid: 129)
[2018-09-21 19:09:44 -0500] [126] [INFO] Worker exiting (pid: 126)
[2018-09-22 00:09:44 +0000] [132] [INFO] Booting worker with pid: 132
[2018-09-22 00:09:44 +0000] [135] [INFO] Booting worker with pid: 135
[2018-09-22 00:11:12 +0000] [17] [INFO] Starting gunicorn 19.5.0
[2018-09-22 00:11:12 +0000] [17] [INFO] Listening at: http://0.0.0.0:9000 (17)
[2018-09-22 00:11:12 +0000] [17] [INFO] Using worker: sync
[2018-09-22 00:11:12 +0000] [20] [INFO] Booting worker with pid: 20
[2018-09-22 00:11:12 +0000] [22] [INFO] Booting worker with pid: 22
Not Found: /favicon.ico
[2018-09-21 19:18:46 -0500] [20] [INFO] Worker reloading: /home/django_app/c_olimpo/admin.py modified
[2018-09-21 19:18:46 -0500] [22] [INFO] Worker reloading: /home/django_app/c_olimpo/admin.py modified
[2018-09-21 19:18:46 -0500] [20] [INFO] Worker exiting (pid: 20)
[2018-09-21 19:18:46 -0500] [22] [INFO] Worker exiting (pid: 22)
[2018-09-22 00:18:46 +0000] [26] [INFO] Booting worker with pid: 26
[2018-09-22 00:18:46 +0000] [28] [INFO] Booting worker with pid: 28
